Workbook
Name Slicer_Cat: #N/A
Name Slicer_State: #N/A

Sheet ev_sales_by_makers_and_cat_15-2
A1: Cat | B1: Maker | C1: 2015 | D1: 2016 | E1: 2017 | F1: 2018 | G1: 2019 | H1: 2020 | I1: 2021 | J1: 2022 | K1: 2023 | L1: 2024 | M1: Total sales
A2: 3W | B2: VOLVO GROUP INDIA PVT LTD | C2: 0 | D2: 0 | E2: 31 | F2: 12 | G2: 0 | H2: 0 | I2: 0 | J2: 0 | K2: 0 | L2: 0 | M2: 43
A3: 3W | B3: 3EV INDUSTRIES PVT LTD | C3: 0 | D3: 0 | E3: 0 | F3: 0 | G3: 0 | H3: 0 | I3: 112 | J3: 390 | K3: 545 | L3: 51 | M3: 1098
A4: 2W | B4: 3GB TECHNOLOGY PVT LTD | C4: 0 | D4: 0 | E4: 0 | F4: 1 | G4: 0 | H4: 0 | I4: 0 | J4: 0 | K4: 0 | L4: 0 | M4: 1
A5: 3W | B5: 3GB TECHNOLOGY PVT LTD | C5: 0 | D5: 1 | E5: 1 | F5: 0 | G5: 0 | H5: 0 | I5: 0 | J5: 0 | K5: 0 | L5: 0 | M5: 2
A6: 3W | B6: 3S INDUSTRIES PRIVATE LIMITED | C6: 0 | D6: 0 | E6: 0 | F6: 0 | G6: 48 | H6: 66 | I6: 43 | J6: 68 | K6: 266 | L6: 578 | M6: 1069
A7: LMV | B7: 3S INDUSTRIES PRIVATE LIMITED | C7: 0 | D7: 0 | E7: 0 | F7: 0 | G7: 3 | H7: 1 | I7: 0 | J7: 0 | K7: 0 | L7: 0 | M7: 4
A8: 3W | B8: A B EXCAVATORS & EARTHMOVER LTD | C8: 0 | D8: 1 | E8: 0 | F8: 0 | G8: 0 | H8: 0 | I8: 0 | J8: 0 | K8: 0 | L8: 0 | M8: 1
A9: 3W | B9: A D AGRO WORKS | C9: 0 | D9: 0 | E9: 2 | F9: 1 | G9: 0 | H9: 0 | I9: 0 | J9: 0 | K9: 0 | L9: 0 | M9: 3
A10: 3W | B10: A K AUTTO ELECTRICAL | C10: 0 | D10: 1 | E10: 72 | F10: 56 | G10: 42 | H10: 1 | I10: 5 | J10: 3 | K10: 2 | L10: 0 | M10: 182
A11: 3W | B11: A K GUPTA & CO. | C11: 0 | D11: 0 | E11: 100 | F11: 625 | G11: 438 | H11: 195 | I11: 256 | J11: 433 | K11: 563 | L11: 355 | M11: 2965
A12: 3W | B12: A P I MOTORS PVT LTD | C12: 0 | D12: 0 | E12: 0 | F12: 2 | G12: 28 | H12: 14 | I12: 20 | J12: 93 | K12: 279 | L12: 146 | M12: 582
A13: LMV | B13: A R T WELDING WORKS | C13: 0 | D13: 1 | E13: 0 | F13: 2 | G13: 0 | H13: 0 | I13: 0 | J13: 0 | K13: 0 | L13: 0 | M13: 3
... A1387: 3W | B1387: ZOHAN TRADERS AND BIG METRO | C1387: 0 | D1387: 0 | E1387: 0 | F1387: 0 | G1387: 0 | H1387: 0 | I1387: 0 | J1387: 5 | K1387: 131 | L1387: 74 | M1387: 210
L1388: Grandtotal | M1388: =SUM(M2:M1387) -> 4420903

Sheet ev_cat_01-24
A1: Date | B1: FOUR WHEELER (INVALID CARRIAGE) | C1: HEAVY GOODS VEHICLE | D1: HEAVY MOTOR VEHICLE | E1: HEAVY PASSENGER VEHICLE | F1: LIGHT GOODS VEHICLE | G1: LIGHT MOTOR VEHICLE | H1: LIGHT PASSENGER VEHICLE | I1: MEDIUM GOODS VEHICLE | J1: MEDIUM PASSENGER VEHICLE | K1: MEDIUM MOTOR VEHICLE | L1: OTHER THAN MENTIONED ABOVE | M1: THREE WHEELER(NT) | N1: TWO WHEELER (INVALID CARRIAGE) | O1: THREE WHEELER(T) | P1: TWO WHEELER(NT) | Q1: TWO WHEELER(T) | R1: Total Registration
A2: 0 | B2: 0 | C2: 0 | D2: 0 | E2: 0 | F2: 0 | G2: 0 | H2: 0 | I2: 0 | J2: 0 | K2: 0 | L2: 0 | M2: 0 | N2: 0 | O2: 0 | P2: 0 | Q2: 0 | R2: =SUM(Table10[[#This Row],[FOUR WHEELER (INVALID CARRIAGE)]:[TWO WHEELER(T)]]) -> 0
A3: 36892 | B3: 0 | C3: 1 | D3: 0 | E3: 0 | F3: 9 | G3: 15 | H3: 1 | I3: 0 | J3: 0 | K3: 0 | L3: 2 | M3: 0 | N3: 0 | O3: 2 | P3: 62 | Q3: 0 | R3: =SUM(Table10[[#This Row],[FOUR WHEELER (INVALID CARRIAGE)]:[TWO WHEELER(T)]]) -> 92 | T3: =ISNUMBER(A2) -> TRUE
A4: 37257 | B4: 0 | C4: 2 | D4: 1 | E4: 0 | F4: 266 | G4: 11 | H4: 5 | I4: 0 | J4: 0 | K4: 0 | L4: 0 | M4: 0 | N4: 0 | O4: 2 | P4: 11 | Q4: 0 | R4: =SUM(Table10[[#This Row],[FOUR WHEELER (INVALID CARRIAGE)]:[TWO WHEELER(T)]]) -> 298
A5: 37622 | B5: 0 | C5: 1 | D5: 2 | E5: 0 | F5: 35 | G5: 15 | H5: 1 | I5: 0 | J5: 0 | K5: 0 | L5: 1 | M5: 0 | N5: 0 | O5: 9 | P5: 18 | Q5: 0 | R5: =SUM(Table10[[#This Row],[FOUR WHEELER (INVALID CARRIAGE)]:[TWO WHEELER(T)]]) -> 82
A6: 37987 | B6: 0 | C6: 2 | D6: 0 | E6: 1 | F6: 14 | G6: 17 | H6: 1 | I6: 0 | J6: 0 | K6: 1 | L6: 2 | M6: 0 | N6: 0 | O6: 1 | P6: 21 | Q6: 0 | R6: =SUM(Table10[[#This Row],[FOUR WHEELER (INVALID CARRIAGE)]:[TWO WHEELER(T)]]) -> 60
A7: 38353 | B7: 0 | C7: 0 | D7: 0 | E7: 0 | F7: 10 | G7: 14 | H7: 1 | I7: 0 | J7: 0 | K7: 0 | L7: 0 | M7: 0 | N7: 0 | O7: 1 | P7: 38 | Q7: 0 | R7: =SUM(Table10[[#This Row],[FOUR WHEELER (INVALID CARRIAGE)]:[TWO WHEELER(T)]]) -> 64
A8: 38718 | B8: 0 | C8: 1 | D8: 0 | E8: 0 | F8: 9 | G8: 15 | H8: 1 | I8: 0 | J8: 0 | K8: 0 | L8: 2 | M8: 0 | N8: 0 | O8: 2 | P8: 62 | Q8: 0 | R8: =SUM(Table10[[#This Row],[FOUR WHEELER (INVALID CARRIAGE)]:[TWO WHEELER(T)]]) -> 92
A9: 39083 | B9: 0 | C9: 3 | D9: 3 | E9: 0 | F9: 7 | G9: 20 | H9: 0 | I9: 0 | J9: 0 | K9: 0 | L9: 0 | M9: 0 | N9: 0 | O9: 2 | P9: 119 | Q9: 0 | R9: =SUM(Table10[[#This Row],[FOUR WHEELER (INVALID CARRIAGE)]:[TWO WHEELER(T)]]) -> 154
A10: 39448 | B10: 0 | C10: 0 | D10: 2 | E10: 0 | F10: 6 | G10: 40 | H10: 3 | I10: 0 | J10: 0 | K10: 0 | L10: 2 | M10: 0 | N10: 0 | O10: 2 | P10: 518 | Q10: 0 | R10: =SUM(Table10[[#This Row],[FOUR WHEELER (INVALID CARRIAGE)]:[TWO WHEELER(T)]]) -> 573
A11: 39814 | B11: 0 | C11: 0 | D11: 0 | E11: 0 | F11: 2 | G11: 41 | H11: 0 | I11: 0 | J11: 0 | K11: 0 | L11: 1 | M11: 0 | N11: 0 | O11: 1 | P11: 965 | Q11: 0 | R11: =SUM(Table10[[#This Row],[FOUR WHEELER (INVALID CARRIAGE)]:[TWO WHEELER(T)]]) -> 1010
A12: 40179 | B12: 0 | C12: 0 | D12: 0 | E12: 0 | F12: 7 | G12: 17 | H12: 0 | I12: 0 | J12: 0 | K12: 0 | L12: 0 | M12: 0 | N12: 0 | O12: 4 | P12: 357 | Q12: 0 | R12: =SUM(Table10[[#This Row],[FOUR WHEELER (INVALID CARRIAGE)]:[TWO WHEELER(T)]]) -> 385
A13: 40544 | B13: 0 | C13: 1 | D13: 0 | E13: 0 | F13: 48 | G13: 70 | H13: 0 | I13: 0 | J13: 0 | K13: 0 | L13: 0 | M13: 0 | N13: 0 | O13: 1 | P13: 317 | Q13: 0 | R13: =SUM(Table10[[#This Row],[FOUR WHEELER (INVALID CARRIAGE)]:[TWO WHEELER(T)]]) -> 437
A14: 40909 | B14: 0 | C14: 2 | D14: 0 | E14: 0 | F14: 8 | G14: 87 | H14: 5 | I14: 0 | J14: 0 | K14: 0 | L14: 0 | M14: 0 | N14: 0 | O14: 1 | P14: 560 | Q14: 0 | R14: =SUM(Table10[[#This Row],[FOUR WHEELER (INVALID CARRIAGE)]:[TWO WHEELER(T)]]) -> 663
A15: 41275 | B15: 0 | C15: 3 | D15: 1 | E15: 0 | F15: 5 | G15: 27 | H15: 1 | I15: 0 | J15: 0 | K15: 0 | L15: 0 | M15: 0 | N15: 0 | O15: 2 | P15: 209 | Q15: 0 | R15: =SUM(Table10[[#This Row],[FOUR WHEELER (INVALID CARRIAGE)]:[TWO WHEELER(T)]]) -> 248
... A285: 45261 | B285: 3 | C285: 16 | D285: 0 | E285: 491 | F285: 254 | G285: 7008 | H285: 499 | I285: 0 | J285: 86 | K285: 0 | L285: 0 | M285: 7 | N285: 0 | O285: 57647 | P285: 75748 | Q285: 188 | R285: =SUM(Table10[[#This Row],[FOUR WHEELER (INVALID CARRIAGE)]:[TWO WHEELER(T)]]) -> 141947

Sheet OperationalPC
A1: State | B1: No. of Operational PCS
A2: Andaman & Nicobar | B2: 3
A3: Andhra Pradesh | B3: 327
A4: Arunachal Pradesh | B4: 9
A5: Assam | B5: 86
A6: Bihar | B6: 124
A7: Chandigarh | B7: 12
A8: Chhattisgarh | B8: =SUM(OperationalPC!B3) -> 327
A9: D&D and DNH | B9: 1
A10: Delhi | B10: 1886
A11: Goa | B11: 113
A12: Gujarat | B12: 476
A13: Haryana | B13: 377
A14: Himachal Pradesh | B14: 44
A15: Jammu and Kashmir | B15: 47
A16: Jharkhand | B16: 135
A17: Karnataka | B17: 1041
A18: Kerala | B18: 852
A19: Lakshadweep | B19: 1
A20: Madhya Pradesh | B20: 341
... A35: West Bengal | B35: 318

Sheet Vehicle Class - All
A1: Vehicle Class | B1: Total Registration
A2: FOUR WHEELER (INVALID CARRIAGE) | B2: 21346
A3: HEAVY GOODS VEHICLE | B3: 5870865
A4: HEAVY MOTOR VEHICLE | B4: 102965
A5: HEAVY PASSENGER VEHICLE | B5: 828189
A6: LIGHT GOODS VEHICLE | B6: 10249591
A7: LIGHT MOTOR VEHICLE | B7: 65061773
A8: LIGHT PASSENGER VEHICLE | B8: 4343410
A9: MEDIUM GOODS VEHICLE | B9: 875789
A10: MEDIUM MOTOR VEHICLE | B10: 194600
A11: MEDIUM PASSENGER VEHICLE | B11: 325015
A12: OTHER THAN MENTIONED ABOVE | B12: 1126398
A13: THREE WHEELER(NT) | B13: 679804
... A17: TWO WHEELER(T) | B17: 129181

Sheet EV Maker by Place
A1: EV Maker | B1: Place | C1: State
A2: Tata Motors | B2: Pune | C2: Maharashtra
A3: Mahindra Electric | B3: Bengaluru | C3: Karnataka
A4: Ather Energy | B4: Bengaluru | C4: Karnataka
A5: Hero Electric | B5: New Delhi | C5: Delhi
A6: Ola Electric | B6: Krishnagiri | C6: Tamil Nadu
A7: Ashok Leyland | B7: Chennai | C7: Tamil Nadu
A8: TVS Motor Company | B8: Hosur | C8: Tamil Nadu
A9: Bajaj Auto | B9: Pune | C9: Maharashtra
A10: MG Motor India | B10: Halol | C10: Gujarat
A11: Hyundai Motor India | B11: Chennai | C11: Tamil Nadu
A12: Revolt Motors | B12: Gurgaon | C12: Haryana
... A63: Euler Motors | B63: New Delhi | C63: Delhi

Sheet Analysis
A1: Row Labels | B1: Sum of Total sales | D1: Values | J1: Row Labels | K1: Sum of Total sales
A2: 2W | B2: 2279448 | D2: Sum of 2015 | E2: 7752 | J2: OLA ELECTRIC TECHNOLOGIES PVT LTD | K2: 588266
A3: 3W | B3: 1934263 | D3: Sum of 2016 | E3: 49249 | J3: TVS MOTOR COMPANY LTD | K3: 318445
A4: LMV | B4: 206388 | D4: Sum of 2017 | E4: 87019 | J4: ATHER ENERGY PVT LTD | K4: 236387
A5: MMV | B5: 804 | D5: Sum of 2018 | E5: 129763 | J5: HERO ELECTRIC VEHICLES PVT. LTD | K5: 201785
A6: Grand Total | B6: 4420903 | D6: Sum of 2019 | E6: 165786 | J6: BAJAJ AUTO LTD | K6: 198498
D7: Sum of 2020 | E7: 123770 | J7: OKINAWA AUTOTECH PVT LTD | K7: 196182
B8: =MAX(B2:B5) -> 2279448 | D8: Sum of 2021 | E8: 328854 | J8: YC ELECTRIC VEHICLE | K8: 152951
B9: =INDEX(A2:A5,MATCH(B8,B2:B5,0)) -> 2W | D9: Sum of 2022 | E9: 1020533 | G9: Row Labels | H9: Sum of Total sales | J9: AMPERE VEHICLES PRIVATE LIMITED | K9: 141805
D10: Sum of 2023 | E10: 1529234 | G10: ZOHAN TRADERS AND BIG METRO | H10: 210 | J10: SAERA ELECTRIC AUTO PVT LTD | K10: 87481
D11: Sum of 2024 | E11: 978943 | G11: ZHONGXING (IMPORTER:GREENO AUTOMOBILE) | H11: 5 | J11: MAHINDRA & MAHINDRA LIMITED | K11: 84794
G12: ZHONGHUALONG (IMPORTER: POWORO PVT LTD) | H12: 54 | J12: Grand Total | K12: 2206594 | M12: =MAX(K2:K11) -> 588266
G13: ZHEJIANG TIANYING (IMPORTER: NEWTRON ELECTRIC) | H13: 70 | M13: =INDEX(G10:G1205,MATCH(M12,H10:H1205,0)) -> OLA ELECTRIC TECHNOLOGIES PVT LTD
G14: ZHEJIANG LUYUAN (IMPORTER: DYNAM EV TECH) | H14: 75
G15: ZESAR MOTORS PVT LTD | H15: 130
G16: ZERO 21 RENEWABLE ENERGY SOLUTIONS PVT LTD | H16: 69
G17: ZEOPLUS AXIS INDIA PVT. LTD. | H17: 7523
G18: ZENTHIUM EV PVT LTD | H18: 1671
G19: ZENIAK INNOVATION INDIA LTD | H19: 12261
G20: ZBEE INDIA PVT LTD | H20: 21
G21: ZAP (IMPORTER:ELLYSIUM AUTOMOTIVES PVT LTD) | H21: 39
G22: ZAP (HK) (IMPORTER: IZANAU ELECTRIC) | H22: 211
B23: Vehicle Analysis | G23: YUVRAJ INTERNATIONAL | H23: 115
G24: YOUYAKU ELECTRIC (IMPORTER:ONZO EV) | H24: 57
A25: Sum of Total Registration | G25: YOUYAKU ELECTRIC (IMPORTER:NEWTRON ELECTRIC) | H25: 103
A26: 4489948 | C26: Row Labels | D26: Sum of Total Registration | G26: YOUYAKU ELECTRIC (IMPORTER:KRISHIKA EV INDIA) | H26: 23
C27: TWO WHEELER(NT) | D27: 274971646 | G27: YOUYAKU ELECTRIC (IMPORTER:IME VEHICLES PVT LTD) | H27: 450
C28: LIGHT MOTOR VEHICLE | D28: 65061773 | G28: YOUYAKU ELECTRIC (IMPORTER: TVISI ELECTRIC) | H28: 13
C29: THREE WHEELER(T) | D29: 10708473 | G29: YOUYAKU ELECTRIC (IMPORTER: SMOBILITY EV) | H29: 36
C30: LIGHT GOODS VEHICLE | D30: 10249591 | G30: YOUYAKU ELECTRIC (IMPORTER: SHEMA E-VEHICLE) | H30: 3
C31: HEAVY GOODS VEHICLE | D31: 5870865 | G31: YOUYAKU ELECTRIC (IMPORTER: SASDAL ENTERPRISES) | H31: 181
C32: LIGHT PASSENGER VEHICLE | D32: 4343410 | G32: YOUYAKU ELECTRIC (IMPORTER: HOUSTAN INNOVATION) | H32: 191
C33: OTHER THAN MENTIONED ABOVE | D33: 1126398 | G33: YEZDI MOTORS LTD | H33: 2
C34: MEDIUM GOODS VEHICLE | D34: 875789 | G34: YC ELECTRIC VEHICLE PVT LTD | H34: 77
C35: HEAVY PASSENGER VEHICLE | D35: 828189 | G35: YC ELECTRIC VEHICLE | H35: 152951
C36: THREE WHEELER(NT) | D36: 679804 | G36: YANGGUANG LINGMU (IMPORTER: XWLS ELECTRIC) | H36: 24
C37: Grand Total | D37: 374715938 | G37: YANGGUANG LINGMU (IMPORTER: REMARK ELECTRIC) | H37: 53
G38: YANGGUANG LINGMU (IMPORTER: FLYCON MOTORS) | H38: 157
G39: YANGGUANG LINGMU (IMPORTER: ECOINDIA) | H39: 5
G40: YANGGUANG LINGMU (IMPORTER: DURGA FILTERS) | H40: 10
...

Sheet Dashboard
A1: INDIAN EV MARKET ANALYSIS
C3: =GETPIVOTDATA("Total sales",Analysis!$A$1) -> 4420903 | H3: =Analysis!B9 -> 2W | J3: =Analysis!E45 -> TWO WHEELER(NT) | Q3: =Analysis!M13 -> OLA ELECTRIC TECHNOLOGIES PVT LTD | T3: =GETPIVOTDATA("[Measures].[Sum of No of Operational PCS]",Analysis!$B$49) -> 12324 | W3: =GETPIVOTDATA("[Measures].[Sum of No of Operational PCS]",Analysis!$B$49) -> 12324
I4: =Analysis!B9 -> 2W
